Workbook
Name Code: Liste!$A$2:$A$275
Name Description: Liste!$B:$B
Name Prix: Liste!$F$2:$F$275

Sheet Liste
A1: Code | B1: nom | C1: Fournisseur principal | D1: INCI | E1: Catégorie | F1: Prix au kilo | G1: En stock | H1: Remarques et cotations | I1: %PPAI | J1: %PPAI Bio | K1: %CPAI | L1: %CPAI Bio | M1: Fonctions | N1: N°CAS | O1: Impuretés
B2: SustOleo TSB | C2: Inolex | D2: Hydrogenated Rapeseed oil | E2: Co-émulsionnant O/W | H2: Sans palme, 100% NAT, équivalent au beurre de karité, stabilise l'émulsion sans recristalliser (pf = 67°C), apporte de la richesse à l'émulsion
A3: ECH-AMB001 | B3: Ambrette CO2 | C3: Aroma Zone | E3: Extrait CO2
A4: ECH-AMB002 | B4: HE Ambrette | C4: Diffusions Aromatiques | E4: Huile essentielle | F4: 7500
A5: ECH-AMB003 | B5: Ambrette graines extrait CO2 | C5: Diffusions Aromatiques | E5: Extrait CO2
A6: ECH-AMY001 | B6: Amyris | C6: Astier Demarest | E6: Huile essentielle
A7: ECH-AP001 | B7: Poudre d'avoine colloïdale | C7: Aroma Zone | E7: Actif poudre
A8: ECH-AP002 | B8: Lait d'amande douche en poudre | C8: Aroma Zone
A9: ECH-AP003 | B9: Lait de coco en poudre | C9: Aroma Zone
A10: ECH-AP004 | B10: Nelumbo nucifera seeds (poudre) | C10: BPAE
A11: ECH-AP005 | B11: Curcuma Longa Rhizome | C11: BPAE
A12: ECH-AP006 | B12: Natural anhydrous caffeine powder | C12: Naturex | G12: Non
A13: ECH-AP007 | B13: Rutin 95% | C13: Naturex | F13: 254.1 | H13: 254,10(1kg), 182,20(10kg). % utilisation : max 0,5%. pH : from 2 to 7. Solubility : 1% (10% d'après leur labo) in hot glycerin for clear product - In surfactant or aqueous systems: add the blend at the end of the process - In emulsion: add the blend at the end after 40°C.
A14: ECH-AP008 | B14: Poudre Aloe vera BIO | C14: IES Labo
A15: ECH-AP009 | B15: Guarana PE 2,4% Caffeine | C15: Naturex | G15: Non
A16: ECH-AP010 | B16: Spiruline poudre | C16: ? | G16: Non
A17: ECH-AP011 | B17: L-Arginine | C17: Inolex | G17: Non
A18: ECH-AP012 | B18: Moringa poudre | C18: ?
A19: ECH-AP013 | B19: Oxyde de Zinc | C19: Aroma Zone
A20: ECH-AP014 | B20: Lavande fleurs poudre BIO | C20: L'Herbier du Diois
A21: ECH-AP015 | B21: Tomate poudre BIO | C21: L'Herbier du Diois
A22: ECH-AP016 | B22: Bardane racine poudre BIO | C22: L'Herbier du Diois
A23: ECH-AP017 | B23: Réglisse racine poudre BIO | C23: L'Herbier du Diois
A24: ECH-AP018 | B24: Mauve PA poudre BIO | C24: L'Herbier du Diois
A25: ECH-AP019 | B25: Moga Cha BIO | C25: Alveus
A26: ECH-AP020 | B26: Curcuma poudre BIO | C26: L'Herbier du Diois
A27: ECH-AP021 | B27: Iris pâle PA poudre BIO | C27: L'Herbier du Diois
A28: ECH-AP022 | B28: Eucalyptus feuille poudre BIO | C28: L'Herbier du Diois
A29: ECH-AP023 | B29: Citron zeste poudre BIO | C29: L'Herbier du Diois
... A34: ECH-AP028 | B34: Guimauve racine poudre BIO | C34: L'Herbier du Diois
A35: ECH-AP029 | B35: Oat Phylpeel 2000T | C35: Safic Alcan | D35: Avena Sativa Kernel Extract | E35: Flocons | F35: 50
A36: ECH-AP030 | B36: Oat Phylpeel 1000T | C36: Safic Alcan | D36: Avena Sativa Kernel Extract | E36: Flocons | F36: 50
A37: ECH-AP033 | B37: Glucohyami-SAE (Maintenant Glucohyami GL) | C37: Alban Muller | F37: 104.56€/kg (par 25kg), 114.39€/kg (par 5kg) | G37: Non
A38: ECH-AP034 | B38: Sel de la mer morte | C38: Aroma Zone
A39: ECH-AP035 | B39: Farine de café unmilled | C39: Caffe Bueno
A40: ECH-AP036 | B40: Farine de café milled | C40: Caffe Bueno
A41: ECH-AP037 | B41: Argile grade surfine
A42: ECH-AP038 | B42: Kaolin Imercare Opaque
A43: ECH-AP039 | B43: Pigment végétal Rose Patate douce | C43: Aroma Zone | D43: Distarch Phosphate, Anthocyanins, Citric Acid | E43: Colorant
A44: ECH-AP040 | B44: SpecWhite 02 | C44: Maprecos | D44: Ascorbyl Glucoside | E44: Vitamine C forme stable | H44: Attention peut devenir orange (restaer à un pH de 6,5)
...

Sheet Descriptions
B3: ECH-AP | C3: Actifs poudre | E3: Mise à jour prix MP : le 5.02.2024
B4: ECH-CON | C4: Conservateurs
B5: ECH-HBC | C5: Huiles, beurres et cires
B6: ECH-HY | C6: Hydrolats
B7: ECH-LIQ | C7: Actifs liquides
B8: ECH-PAR | C8: Parfums
B9: ECH-TAR | C9: Tensioactifs, MP de rhéologie
B10: ECH-XXX001 | C10: Huile essentielle (avec 3 premières lettres)
B13: MP00 | C13: Actifs techniques objectivés
B14: MP100 | C14: Huiles végétales
B15: MP150 | C15: Esters
B16: MP200 | C16: Hydrolats
B17: MP300 | C17: Moussants
... B25: MP1000IN | C25: Infusion maison
B28: Pour l'onglet emballage :
B29: ECH-EMB | C29: échantillon d'emballage

Sheet Code formule
A1: OF | B1: Nom OF
A2: F001 | B2: MASQUE EXFOLIANT AUX ACIDES DE FRUITS
A3: F001B | B3: MASQUE EXFOLIANT AUX ACIDES DE FRUITS REFORMULATION
A4: F002 | B4: HUILE INTENSE DÉMAQUILLANTE AUX ANTIOXYDANTS
A5: F002B | B5: HUILE INTENSE DÉMAQUILLANTE AUX ANTIOXYDANTS
A6: F003
A7: F004 | B7: CRÈME REVEIL MULTIVITAMINÉE
A8: F005 | B8: CRÈME CONCENTRÉE AUX ACTIFS REPULPANTS
A9: F006 | B9: SÉRUM OLÉAGINEUX ULTRA-NOURISSANT
A10: F007 | B10: BRUME AUX ACTIFS ANTI-POLLUTION
A11: F008 | B11: CRÈME DE NUITS AUX ACTIFS OXYGÉNANTS
A12: F009 | B12: HUILE DU TIGRE MASSAGE POUR SPORTIFS
A13: F010 | B13: BONNE NUIT GEL DOUCHE
A14: F011 | B14: SÉRUM SUPER PLANTES ANTIOXYDANTES
A15: F012 | B15: BRUME HYDRATANTE AUX FLEURS MÉDITERRANÉENNES
A16: F013 | B16: LOTION PERFECTION AUX ACTIFS ASSAINISSANTS
A17: F014 | B17: SÉRUM SYNERGIE ESSENTIELLE PURIFIANT
A18: F015 | B18: L'AMANDIER HUILE CORPS ET CHEVEUX
... A26: F023 | B26: FLUIDE PEAU PARFAITE
A27: F024
A28: F025 | B28: LAIT DOUCEUR VANILLE NETTOYANT
A29: F026 | B29: HUILE DOUCE AUX FLEURS DÉMAQUILLANTE ET NETTOYANTE
A30: F026B | B30: HUILE DOUCE AUX FLEURS DÉMAQUILLANTE ET NETTOYANTE
A31: F027 | B31: MOUSSE DOUCEUR NETTOYANTE ANTI-TIRAILLEMENT
A32: F028
A33: F029 | B33: SUCRE VANILLÉ GOMMAGE GOURMAND POUR LE CORPS
A34: F030 | B34: HUILE DES ILES
A35: F031 | B35: SÉRUM ILLUMINATEUR DE LA ROSERAIE
A36: F031B | B36: SÉRUM ILLUMINATEUR DE LA ROSERAIE B
A37: F032 | B37: MASQUE ROSE LACTÉ APAISANT
A38: F033 | B38: SÉRUM CONCENTRÉ DE SOLEIL
A39: KID034 | B39: GELEE LAVANTE FLEUR VANILLEE
A40: KID035 | B40: BAUME FONDANT MAMAN BÉBÉ
A41: F036 | B41: SOIN LISSANT AUX FLEURS
A42: F037 | B42: GEL REVEIL ANTI-CERNES
A43: KID038 | B43: LA CREME DES BEBES
A44: KID039 | B44: POMMADE MAGIQUE
... A53: F048 | B53: GOMMAGE NOURRISSANT SUCRE VANILLE

Sheet Code MO
A1: Code | B1: Description | C1: Prix unitaire 2024 en € | D1: Coût par pdt
A2: MOFAB001 | B2: Fabrication Huile avec chauffe | C2: =2.3*33.84 -> 77.832 | D2: NA
A3: MOFAB002 | B3: Fabrication Huile sans chauffe | C3: =1.3*33.84 -> 43.992 | D3: NA
A4: MOFAB003 | B4: Fabrication émulsion | C4: =6*33.84 -> 203.04 | D4: NA
A5: MOFAB004 | B5: Fabrication gel aqueux (type gelée noire) | C5: =6*33.84 -> 203.04 | D5: NA
A6: MOFAB005 | B6: Fabrication gel aqueux chauffe (type masque exfoliant) | C6: =4*33.84 -> 135.36 | D6: NA
A7: MOFAB006 | B7: Fabrication lotion non chauffée (brume) | C7: =3*33.84 -> 101.52 | D7: NA
A8: MOFAB007 | B8: Fabrication gel douche avec chauffe | C8: =4*33.84 -> 135.36 | D8: NA
A9: MOFAB008 | B9: Fabrication lotion chauffée (type brume, mousse) | C9: =4*33.84 -> 135.36 | D9: NA
A10: MOCOND001 | B10: Conditionnement airless 50ml (2200pcs) | C10: 198.66 | D10: =C10/2200 -> 0.0903
A11: MOCOND002 | B11: Conditionnement flacon 120ml avec pré-remplissage (1000pcs) | C11: 142 | D11: =C11/1000 -> 0.142
A12: MOCOND0021 | B12: Conditionnement flacon 50ml avec pré-remplissage (2400pcs) | C12: =142*2 -> 284 | D12: =C12/2400 -> 0.11833333
A13: MOCOND003 | B13: Conditionnement sérum 15ml (8000pcs) | C13: 170 | D13: =C13/8000 -> 0.02125
A14: MOCOND004 | B14: Conditionnement flacon 120ml (1000pcs) | C14: 71 | D14: =C14/1000 -> 0.071
A15: MOCOND005 | B15: Conditionnement flacon 200ml (500pcs) | C15: 71 | D15: =C15/500 -> 0.142
A16: MOCOND006 | B16: Conditionnement flacon 200ml avec pré-remplissage (500pcs) | C16: 142 | D16: =C16/500 -> 0.284
A17: MOCOND007 | B17: Conditionnement flacon 120ml ac difficulté (vrac bullée)(1000pcs) | C17: 100 | D17: =C17/1000 -> 0.1
A18: MOCOND008 | B18: Conditionnement flacon 115ml mousse (1000pcs) | C18: 71 | D18: =C18/1000 -> 0.071
A19: MOCOND009 | B19: Conditionnement flacon 5ml bille (2000pcs) | C19: 200 | D19: =C19/2000 -> 0.1

Sheet Emballages
A1: Code emballage | B1: Description emballage | C1: Fournisseurs | D1: Prix unitaire | E1: Catégorie | F1: Remarque
A2: BILLEINO5 | B2: Bille roll on inox 5ml | C2: Esobea | D2: 0.2
A3: CAAE008 | B3: ETUI AAE008 | C3: LECAGRAPHICS | D3: 0.2361
A4: CAAE032 | B4: ETUI AAE032 | C4: LECAGRAPHICS | D4: 0.2361
A5: CANO001 | B5: ETUI ANO001 | C5: LECAGRAPHICS | D5: 0.2361
A6: CANO001B | B6: ETUI ANO001B | C6: VIMER
A7: CANO004 | B7: ETUI ANO004 | C7: LECAGRAPHICS | D7: 0.2361
A8: CANO011 | B8: ETUI ANO011 | C8: LECAGRAPHICS | D8: 0.46712
A9: CANO033 | B9: ETUI ANO033 | C9: LECAGRAPHICS | D9: 0.46712
A10: CAP001-120 | B10: POMPE FLACON 120 ml | C10: YUYAO H.B.PACKAGING CO.,LTD. | D10: 0.11
A11: CAP002-120 | B11: SPRAY FLACON 120 ml | C11: YUYAO H.B.PACKAGING CO.,LTD. | D11: 0.056
A12: CAP002-50 | B12: SPRAY FLACON 50 ml | C12: YUYAO H.B.PACKAGING CO.,LTD. | D12: 0.056
A13: CAP003 | B13: BOUCHON CHAPEAU CHINOIS | C13: YUYAO H.B.PACKAGING CO.,LTD. | D13: 0.025
A14: CAP004 | B14: POMPE AUTO BLOQUANTE 24/410 BLANCHE | C14: SILGAN | D14: 0.35
A15: CAPAIR50 | B15: Airless bouchon 50ml | C15: APTAR | D15: 0.383
A16: CAPFOAM115 | B16: FOAM PUMP MILKY WHITE | C16: TALENTS PACKING INTERNATIONAL LIMITED | D16: 0.25
A17: CAPPIPETTE | B17: Compte goutte pipette | C17: Esobea | D17: 0.28
A18: CAPPIPETTE05 | B18: Compte goutte pipette 5 ml | C18: EUROVETROCAP | D18: 0.27175
... A39: CPUR023 | B39: ETUI PUR023 | C39: LECAGRAPHICS | D39: 0.2361
A40: CPUR041 | B40: ETUI PUR041 | C40: VIMER
A41: CREG005 | B41: ETUI REG005 | C41: LECAGRAPHICS | D41: 0.2361
A42: CREG006 | B42: ETUI REG006 | C42: LECAGRAPHICS | D42: 0.46712
A43: CREG036 | B43: ETUI REG036 | C43: VIMER | D43: 0.4
A44: DAAE027 | B44: DOYPACK AAE027 250 ml | C44: Sealester | D44: 0.62
A45: DHYD025 | B45: DOYPACK HYD025 250 ml | C45: Sealester | D45: 0.62
A46: DPUR016 | B46: DOYPACK PUR016 250 ml | C46: Sealester | D46: 0.62
A47: DPUR017 | B47: DOYPACK PUR017 250 ml | C47: Sealester | D47: 0.62
A48: EAAE007 | B48: ETIQUETTE EAAE007 | C48: LABEL IMPRIME | D48: 0.2287
A49: EAAE008 | B49: ETIQUETTE AAE008 | C49: LABEL IMPRIME | D49: 0.072
A50: EAAE027 | B50: ETIQUETTE AAE027 | C50: LABEL IMPRIME | D50: 0.159
A51: EAAE032 | B51: ETIQUETTE AAE032 | C51: LABEL IMPRIME | D51: 0.072
A52: EAAEV007 | B52: ETIQUETTE EAAVE007 | C52: LABEL IMPRIME | D52: 0.1355
A53: EANO001 | B53: ETIQUETTE ANO001 | C53: LABEL IMPRIME | D53: 0.007737
A54: EANO001B | B54: ETIQUETTE ANO001B | C54: LABEL IMPRIME
A55: EANO002 | B55: ETIQUETTE ANO002 | C55: LABEL IMPRIME | D55: 0.0932
A56: EANO004 | B56: ETIQUETTE ANO004 | C56: LABEL IMPRIME | D56: 0.072
A57: EANO011 | B57: ETIQUETTE ANO011 | C57: LABEL IMPRIME | D57: 0.1
A58: EANO033 | B58: ETIQUETTE ANO033 | C58: LABEL IMPRIME | D58: 0.1
A59: EANOV002 | B59: ETIQUETTE ANOV002 | C59: LABEL IMPRIME | D59: 0.1355
A60: EANOV011 | B60: ETIQUETTE ANOV011 | C60: LABEL IMPRIME | D60: 0.04
...

Sheet Allergènes 81
A2: % de la substance allergène dans la matière première | F2: Allergènes | G2: Benzyl alcohol | H2: 6-Methylcoumarin | I2: Citral | J2: Geranial | K2: Neral | L2: Isoeugenol | M2: Isoeugenol | N2: Isoeugenol | O2: Citronellol | P2: Citronellol | Q2: Citronellol | R2: Citronellol | S2: Limonene | T2: Limonene | U2: Limonene | V2: Limonene | W2: Pinus Mugo Leaf Oil Pinus Mugo Twig Leaf Extract Pinus Mugo Twig Oil | X2: Pinus Pumila needle extract Pinus Pumila Twig Leaf Extract Pinus Pumila Twig Leaf Oil | Y2: Cedrus Atlantica Bark Extract Cedrus Atlantica Bark Oil Cedrus Atlantica Bark Water Cedrus Atlantica Leaf Extract Cedrus Atlantica Wood Extract Cedrus Atlantica Wood Oil | Z2: Cedrus Atlantica Bark Extract Cedrus Atlantica Bark Oil Cedrus Atlantica Bark Water Cedrus Atlantica Leaf Extract Cedrus Atlantica Wood Extract Cedrus Atlantica Wood Oil | AA2: Turpentine | AB2: Turpentine | AC2: Turpentine | AD2: Alpha-terpinene | AE2: Terpinolene | AF2: Myroxylon Balsamum Pereirae Balsam Extract; Myroxylon Balsamum Pereirae Balsam Oil; Myroxylon Pereirae Oil; Myroxylon Pereirae Resin Extract; Myroxylon Pereirae Resin | AG2: Aalpha-Damascone; cis-Rose ketone 1 cis Rose ketone 2 (cis-beta-Damascone) trans-Rose ketone 2 (trans-beta-Damascone) | AH2: Aalpha-Damascone; cis-Rose ketone 1 | AI2: trans-Rose ketone 1 | AJ2: Rose ketone 4 (Damascenone) | AK2: Rose ketone 3 (delta-Damascone) | AL2: trans-Rose ketone 3 | AM2: cis Rose ketone 2 (cis-beta-Damascone) | AN2: trans-Rose ketone 2 (trans-beta-Damascone) | AO2: 3-Propylidenephthalide | AP2: Lippia citriodora absolute | AQ2: Lippia citriodora absolute | AR2: Acetyl Cedrene | AS2: Amyl Salicylate | AT2: Anethole | AU2: Anethole | AV2: Benzaldehyde | AW2: Camphor | AX2: Camphor | AY2: Camphor | AZ2: Camphor | BA2: Beta-Caryophyllene | BB2: Carvone | BC2: Carvone | BD2: Carvone | BE2: Dimethyl phenethyl Acetate | BF2: Hexadecanolactone | BG2: Hexamethylindanopyran | BH2: Linalyl Acetate | BI2: Menthol | BJ2: Menthol | BK2: Menthol | BL2: Menthol | BM2: Methyl Salicylate | BN2: Ebanol | BO2: Salicylaldehyde | BP2: Santalol | BQ2: Santalol | BR2: Santalol | BS2: Sclareol | BT2: Terpineol | BU2: Alpha Terpineol | BV2: Terpineol | BW2: Terpineol | BX2: Tetramethyl acetyloctahydronaphthalenes | BY2: Tetramethyl acetyloctahydronaphthalenes | BZ2: Tetramethyl acetyloctahydronaphthalenes | CA2: Tetramethyl acetyloctahydronaphthalenes | CB2: Trimethylbenzenepropanol | CC2: Vanillin | CD2: Cananga Odorata Flower Extract | CE2: Cananga Odorata Flower Extract | CF2: Cananga Odorata Flower Oil | CG2: Cananga Odorata Flower Oil | CH2: Cinnamomum Cassia Leaf Oil | CI2: Cinnamomum Cassia Leaf Oil | CJ2: Cinnamomum Zeylanicum Bark Oil | CK2: Cinnamomum Zeylanicum Bark Oil | CL2: Citrus Aurantium Amara Flower Oil | CM2: Citrus Aurantium Dulcis Flower Oil | CN2: Citrus Aurantium Dulcis Flower Oil | CO2: Citrus Aurantium Amara Peel Oil Citrus Sinensis Peel Oil | CP2: Citrus Aurantium Amara Peel Oil | CQ2: Citrus Sinensis Peel Oil | CR2: Citrus Aurantium Dulcis Peel Oil; Citrus Sinensis Peel Oil | CS2: Citrus Aurantium Dulcis Peel Oil; Citrus Sinensis Peel Oil | CT2: Citrus Aurantium Bergamia Peel Oil | CU2: Citrus Aurantium Bergamia Peel Oil | CV2: Citrus Aurantium Bergamia Peel Oil | CW2: Citrus Aurantium Bergamia Peel Oil | CX2: Citrus Aurantium Bergamia Peel Oil | CY2: Citrus Limon Peel Oil | CZ2: Citrus Limon Peel Oil | DA2: Cymbopogon Schoenantus Oil | DB2: Cymbopogon Schoenantus Oil | DC2: Cymbopogon Citratus Leaf Oil Cymbopogon Flexuosus Oil | DD2: Eucalyptus Globulus Leaf Oil Eucalyptus Globulus Leaf/Twig Oil | DE2: Eucalyptus Globulus Leaf Oil Eucalyptus Globulus Leaf/Twig Oil | DF2: Eugenia Caryophyllus Leaf Oil Eugenia Caryophyllus Flower Oil Eugenia Caryophyllus Stem Oil Eugenia Caryophyllus Bud Oil | DG2: Eugenia Caryophyllus Leaf Oil Eugenia Caryophyllus Flower Oil Eugenia Caryophyllus Stem Oil Eugenia Caryophyllus Bud Oil | DH2: Eugenia Caryophyllus Leaf Oil Eugenia Caryophyllus Flower Oil Eugenia Caryophyllus Stem Oil Eugenia Caryophyllus Bud Oil | DI2: Jasminum Grandiflorum Flower Extract; Jasminum Officinale Oil Jasminum Officinale Flower Extract; | DJ2: Jasminum Grandiflorum Flower Extract; Jasminum Officinale Oil Jasminum Officinale Flower Extract; | DK2: Jasminum Grandiflorum Flower Extract; Jasminum Officinale Oil Jasminum Officinale Flower Extract; | DL2: Jasminum Grandiflorum Flower Extract; Jasminum Officinale Oil Jasminum Officinale Flower Extract; | DM2: Jasminum Grandiflorum Flower Extract; Jasminum Officinale Oil Jasminum Officinale Flower Extract; | DN2: Juniperus Virginiana Oil; Juniperus Virginiana Wood Oil | DO2: Laurus Nobilis Leaf Oil | DP2: Laurus Nobilis Leaf Oil | DQ2: Laurus Nobilis Leaf Oil | DR2: Lavandula Hybrida Oil; Lavandula Hybrida Extract; Lavandula Hybrida Flower Extract; | DS2: Lavandula Hybrida Oil; Lavandula Hybrida Extract; Lavandula Hybrida Flower Extract; | DT2: Lavandula Hybrida Oil; Lavandula Hybrida Extract; Lavandula Hybrida Flower Extract; | DU2: Lavandula Hybrida Oil; Lavandula Hybrida Extract; Lavandula Hybrida Flower Extract; | DV2: Lavandula Hybrida Oil; Lavandula Hybrida Extract; Lavandula Hybrida Flower Extract; | DW2: Lavandula Intermedia Flower/Leaf/Stem Extract; Lavandula Intermedia Flower/Leaf/Stem Oil; Lavandula intermedia Oil Lavendula Angustifolia Oil; Lavendula Angustifolia Flower/Leaf/Stem Extract | DX2: Lavandula Intermedia Flower/Leaf/Stem Extract; Lavandula Intermedia Flower/Leaf/Stem Oil; Lavandula intermedia Oil Lavendula Angustifolia Oil; Lavendula Angustifolia Flower/Leaf/Stem Extract | DY2: Mentha Piperita Oil | DZ2: Mentha Piperita Oil | EA2: Mentha Viridis Leaf Oil | EB2: Mentha Viridis Leaf Oil | EC2: Narcissus Poeticus Extract Narcissus Pseudonarcissus Flower Extract Narcissus Jonquilla Extract Narcissus Tazetta Extract | ED2: Narcissus Poeticus Extract Narcissus Pseudonarcissus Flower Extract Narcissus Jonquilla Extract Narcissus Tazetta Extract | EE2: Narcissus Poeticus Extract Narcissus Pseudonarcissus Flower Extract Narcissus Jonquilla Extract Narcissus Tazetta Extract | EF2: Narcissus Poeticus Extract Narcissus Pseudonarcissus Flower Extract Narcissus Jonquilla Extract Narcissus Tazetta Extract | EG2: Pelargonium Graveolens Flower Oil | EH2: Pelargonium Graveolens Flower Oil | EI2: Pogostemon Cablin Oil | EJ2: Pogostemon Cablin Oil | EK2: Rosa Damascena Flower Oil; Rosa Damascena Flower Extract Rosa Alba Flower Oil; Rosa Alba Flower Extract Rosa Canina Fruit Oil Rosa Centifolia Flower Oil; Rosa Centifolia Flower Extract Rosa Gallica Flower Oil Rosa Moschata Flower Oil Rosa Rugosa Flower Oil | EL2: Rosa Damascena Flower Oil; Rosa Damascena Flower Extract Rosa Alba Flower Oil; Rosa Alba Flower Extract Rosa Canina Fruit Oil Rosa Centifolia Flower Oil; Rosa Centifolia Flower Extract Rosa Gallica Flower Oil Rosa Moschata Flower Oil Rosa Rugosa Flower Oil | EM2: Rosa Damascena Flower Oil; Rosa Damascena Flower Extract Rosa Alba Flower Oil; Rosa Alba Flower Extract Rosa Canina Fruit Oil Rosa Centifolia Flower Oil; Rosa Centifolia Flower Extract Rosa Gallica Flower Oil Rosa Moschata Flower Oil Rosa Rugosa Flower Oil | EN2: Rosa Damascena Flower Oil; Rosa Damascena Flower Extract Rosa Alba Flower Oil; Rosa Alba Flower Extract Rosa Canina Fruit Oil Rosa Centifolia Flower Oil; Rosa Centifolia Flower Extract Rosa Gallica Flower Oil Rosa Moschata Flower Oil Rosa Rugosa Flower Oil | EO2: Rosa Damascena Flower Oil; Rosa Damascena Flower Extract Rosa Alba Flower Oil; Rosa Alba Flower Extract Rosa Canina Fruit Oil Rosa Centifolia Flower Oil; Rosa Centifolia Flower Extract Rosa Gallica Flower Oil Rosa Moschata Flower Oil Rosa Rugosa Flower Oil | EP2: Rosa Damascena Flower Oil; Rosa Damascena Flower Extract Rosa Alba Flower Oil; Rosa Alba Flower Extract Rosa Canina Fruit Oil Rosa Centifolia Flower Oil; Rosa Centifolia Flower Extract Rosa Gallica Flower Oil Rosa Moschata Flower Oil Rosa Rugosa Flower Oil | EQ2: Rosa Damascena Flower Oil; Rosa Damascena Flower Extract Rosa Alba Flower Oil; Rosa Alba Flower Extract Rosa Canina Fruit Oil Rosa Centifolia Flower Oil; Rosa Centifolia Flower Extract Rosa Gallica Flower Oil Rosa Moschata Flower Oil Rosa Rugosa Flower Oil | ER2: Santalum Album Oil | ES2: Santalum Album Oil | ET2: Eugenyl Acetate | EU2: Geranyl Acetate | EV2: Isoeugenyl Acetate | EW2: Pinene | EX2: Pinene | EY2: Pinene | EZ2: Pinene | FA2: Cinnamyl alcohol | FB2: Eugenol | FC2: Hydroxycitronellal | FD2: Amyl cinnamal | FE2: Amylcinnamyl alcohol | FF2: Benzyl salicylate | FG2: Cinnamal | FH2: Coumarin | FI2: Geraniol | FJ2: Anise alcohol | FK2: Benzyl cinnamate | FL2: Farnesol | FM2: Linalool | FN2: Benzyl benzoate | FO2: Hexyl cinnamal | FP2: Methyl 2-octynoate | FQ2: Alpha isomethyl ionone
A3: Code MP | B3: Description | C3: INCI | D3: Nom commercial | E3: Fournisseur | F3: N°CAS | G3: 100-51-6 | H3: 92-48-8 | I3: 5392-40-5 | J3: 141-27-5 | K3: 106-26-3 | L3: 97-54-1 | M3: 5932-68-3 | N3: 5912-86-7 | O3: 106-22-9 | P3: 26489-01-0 | Q3: 1117-61-9 | R3: 7540-51-4 | S3: 138-86-3 | T3: 7705-14-8 | U3: 5989-27-5 | V3: 5989-54-8 | W3: 90082-72-7 | X3: 97676-05-6 | Y3: 92201-55-3 | Z3: 8023-85-6 | AA3: 9005-90-7 | AB3: 8006-64-2 | AC3: 8052-14-0 | AD3: 99-86-5 | AE3: 586-62-9 | AF3: 8007-00-9 | AG3: 43052-87-5 | AH3: 23726-94-5 | AI3: 24720-09-0 | AJ3: 23696-85-7 | AK3: 57378-68-4 | AL3: 71048-82-3 | AM3: 23726-92-3 | AN3: 23726-91-2 | AO3: 17369-59-4 | AP3: 8024-12-2 | AQ3: 85116-63-8 | AR3: 32388-55-9 | AS3: 2050-08-0 | AT3: 104-46-1 | AU3: 4180-23-8 | AV3: 100-52-7 | AW3: 76-22-2 | AX3: 21368-68-3 | AY3: 464-49-3 | AZ3: 464-48-2 | BA3: 87-44-5 | BB3: 99-49-0 | BC3: 6485-40-1 | BD3: 2244-16-8 | BE3: 151-05-3 | BF3: 109-29-5 | BG3: 1222-05-5 | BH3: 115-95-7 | BI3: 89-78-1 | BJ3: 1490-04-6 | BK3: 2216-51-5 | BL3: 15356-60-2 | BM3: 119-36-8 | BN3: 67801-20-1 | BO3: 90-02-8 | BP3: 11031-45-1 | BQ3: 115-71-9 | BR3: 77-42-9 | BS3: 515-03-7 | BT3: 8000-41-7 | BU3: 98-55-5 | BV3: 138-87-4 | BW3: 586-81-2 | BX3: 54464-57-2 | BY3: 54464-59-4 | BZ3: 68155-66-8 | CA3: 68155-67-9 | CB3: 103694-68-4 | CC3: 121-33-5 | CD3: 83863-30-3 | CE3: 8006-81-3 | CF3: 68606-83-7 | CG3: 93686-30-7 | CH3: 8007-80-5 | CI3: 84961-46-6 | CJ3: 8015-91-6 | CK3: 84649-98-9 | CL3: 72968-50-4 | CM3: 8028-48-6 | CN3: 8016-38-4 | CO3: 68916-04-1 | CP3: 72968-50-4 | CQ3: 97766-30-8 | CR3: 8028-48-6 | CS3: 8008-57-9 | CT3: 8007-75-8 | CU3: 89957-91-5 | CV3: 68648-33-9 | CW3: 8007-75-8 | CX3: 85049-52-1 | CY3: 84929-31-7 | CZ3: 8008-56-8 | DA3: 8007-02-1 | DB3: 89998-16-3 | DC3: 91844-92-7 | DD3: 97926-40-4 | DE3: 8000-48-4 | DF3: 8000-34-8 | DG3: 84961-50-2 | DH3: 8015-97-2 | DI3: 84776-64-7 | DJ3: 90045-94-6 | DK3: 8022-96-6 | DL3: 8024-43-9 | DM3: 90045-94-6 | DN3: 8000-27-9/ 85085-41-2 | DO3: 8002-41-3 | DP3: 8007-48-5 | DQ3: 84603-73-6 | DR3: 91722-69-9 | DS3: 8022-15-9 | DT3: 93455-96-0 | DU3: 93455-97-1 | DV3: 92623-76-2 | DW3: 8000-28-0 | DX3: 90063-37-9 | DY3: 8006-90-4 | DZ3: 84082-70-2 | EA3: 8008-79-5 | EB3: 84696-51-5 | EC3: 90064-26-9 | ED3: 68917-12-4 | EE3: 90064-27-0 | EF3: 90064-25-8 | EG3: 90082-51-2 | EH3: 8000-46-2 | EI3: 8014-09-3 | EJ3: 84238-39-1 | EK3: 8007-01-0 | EL3: 90106-38-0 | EM3: 93334-48-6 | EN3: 84696-47-9 | EO3: 84604-12-6 | EP3: 84604-13-7 | EQ3: 92347-25-6 | ER3: 8006-87-9 | ES3: 84787-70-2 | ET3: 93-28-7 | EU3: 105-87-3 | EV3: 93-29-8 | EW3: 80-56-8 | EX3: 7785-70-8 | EY3: 127-91-3 | EZ3: 18172-67-3 | FA3: 104-54-1 | FB3: 97-53-0 | FC3: 107-75-5 | FD3: 122-40-7 | FE3: 101-85-9 | FF3: 118-58-1 | FG3: 104-55-2 | FH3: 91-64-5 | FI3: 106-24-1 | FJ3: 105-13-5 | FK3: 103-41-3 | FL3: 4602-84-0 | FM3: 78-70-6 | FN3: 120-51-4 | FO3: 101-86-0 | FP3: 111-12-6 | FQ3: 127-51-5
F4: Groupement de nom | I4: Citral | J4: Citral | K4: Citral | W4: Pinus Mugo | X4: Pinus Pumila | Y4: Cedrus Atlantica | Z4: Cedrus Atlantica | AF4: Myroxylon Pereirae Oil/Extract | AG4: Rose Ketones | AH4: Rose Ketones | AI4: Rose Ketones | AJ4: Rose Ketones | AK4: Rose Ketones | AL4: Rose Ketones | AM4: Rose Ketones | AN4: Rose Ketones | CD4: Cananga Odorata Oil/Extract | CE4: Cananga Odorata Oil/Extract | CF4: Cananga Odorata Oil/Extract | CG4: Cananga Odorata Oil/Extract | CL4: Citrus Aurantium Flower Oil | CM4: Citrus Aurantium Flower Oil | CN4: Citrus Aurantium Flower Oil | CO4: Citrus Aurantium Peel oil | CP4: Citrus Aurantium Peel oil | CQ4: Citrus Aurantium Peel oil | CR4: Citrus Aurantium Peel oil | CS4: Citrus Aurantium Peel oil | DA4: Lemongrass Oil | DB4: Lemongrass Oil | DC4: Lemongrass Oil | DD4: Eucalyptus Globulus Oil | DE4: Eucalyptus Globulus Oil | DF4: Eugenia Caryophyllus Oil | DG4: Eugenia Caryophyllus Oil | DH4: Eugenia Caryophyllus Oil | DI4: Jasmine Oil/Extract | DJ4: Jasmine Oil/Extract | DK4: Jasmine Oil/Extract | DL4: Jasmine Oil/Extract | DM4: Jasmine Oil/Extract | DN4: Juniperus Virginiana Oil | DR4: Lavandula Oil/Extract | DS4: Lavandula Oil/Extract | DT4: Lavandula Oil/Extract | DU4: Lavandula Oil/Extract | DV4: Lavandula Oil/Extract | DW4: Lavandula Oil/Extract | DX4: Lavandula Oil/Extract | EC4: Narcissus Extract | ED4: Narcissus Extract | EE4: Narcissus Extract | EF4: Narcissus Extract | EG4: Pelargonium Graveolens Flower Oil | EH4: Pelargonium Graveolens Flower Oil | EK4: Rose Flower Oil/Extract | EL4: Rose Flower Oil/Extract | EM4: Rose Flower Oil/Extract | EN4: Rose Flower Oil/Extract | EO4: Rose Flower Oil/Extract | EP4: Rose Flower Oil/Extract | EQ4: Rose Flower Oil/Extract
A5: 1 | B5: 2 | C5: 3 | D5: 4 | E5: 5 | F5: 6 | G5: 7 | H5: 8 | I5: 9 | J5: 10 | K5: 11 | L5: 12 | M5: 13 | N5: 14 | O5: 15 | P5: 16 | Q5: 17 | R5: 18 | S5: 19 | T5: 20 | U5: 21 | V5: 22 | W5: 23 | X5: 24 | Y5: 25 | Z5: 26 | AA5: 27 | AB5: 28 | AC5: 29 | AD5: 30 | AE5: 31 | AF5: 32 | AG5: 33 | AH5: 34 | AI5: 35 | AJ5: 36 | AK5: 37 | AL5: 38 | AM5: 39 | AN5: 40 | AO5: 41 | AP5: 42 | AQ5: 43 | AR5: 44 | AS5: 45 | AT5: 46 | AU5: 47 | AV5: 48 | AW5: 49 | AX5: 50 | AY5: 51 | AZ5: 52 | BA5: 53 | BB5: 54 | BC5: 55 | BD5: 56 | BE5: 57 | BF5: 58 | BG5: 59 | BH5: 60 | BI5: 61 | BJ5: 62 | BK5: 63 | BL5: 64 | BM5: 65 | BN5: 66 | BO5: 67 | BP5: 68 | BQ5: 69 | BR5: 70 | BS5: 71 | BT5: 72 | BU5: 73 | BV5: 74 | BW5: 75 | BX5: 76 | BY5: 77 | BZ5: 78 | CA5: 79 | CB5: 80 | CC5: 81 | CD5: 82 | CE5: 83 | CF5: 84 | CG5: 85 | CH5: 86 | CI5: 87 | CJ5: 88 | CK5: 89 | CL5: 90 | CM5: 91 | CN5: 92 | CO5: 93 | CP5: 94 | CQ5: 95 | CR5: 96 | CS5: 97 | CT5: 98 | CU5: 99 | CV5: 100 | CW5: 101 | CX5: 102 | CY5: 103 | CZ5: 104 | DA5: 105 | DB5: 106 | DC5: 107 | DD5: 108 | DE5: 109 | DF5: 110 | DG5: 111 | DH5: 112 | DI5: 113 | DJ5: 114 | DK5: 115 | DL5: 116 | DM5: 117 | DN5: 118 | DO5: 119 | DP5: 120 | DQ5: 121 | DR5: 122 | DS5: 123 | DT5: 124 | DU5: 125 | DV5: 126 | DW5: 127 | DX5: 128 | DY5: 129 | DZ5: 130 | EA5: 131 | EB5: 132 | EC5: 133 | ED5: 134 | EE5: 135 | EF5: 136 | EG5: 137 | EH5: 138 | EI5: 139 | EJ5: 140 | EK5: 141 | EL5: 142 | EM5: 143 | EN5: 144 | EO5: 145 | EP5: 146 | EQ5: 147 | ER5: 148 | ES5: 149 | ET5: 150 | EU5: 151 | EV5: 152 | EW5: 153 | EX5: 154 | EY5: 155 | EZ5: 156 | FA5: 157 | FB5: 158 | FC5: 159 | FD5: 160 | FE5: 161 | FF5: 162 | FG5: 163 | FH5: 164 | FI5: 165 | FJ5: 166 | FK5: 167 | FL5: 168 | FM5: 169 | FN5: 170 | FO5: 171 | FP5: 172 | FQ5: 173
A6: MP501B | B6: He d'ylang ylang complète BIO | C6: CANANGA ODORATA FLOWER OIL | D6: YLANG COMPLETE HE BIO | E6: Diffusions aromatiques | G6: 0 | H6: 1 | I6: 0
A7: MP502 | B7: He Vetiver Haïti BIO | C7: VETIVERIA ZIZANOIDES ROOT OIL | D7: VETYVER HAITI HUILE ESSENTIELLE | E7: Astier Demarest | M7: 0.06 | S7: 0.004 | BA7: 0.015 | EW7: 0.034 | EY7: 0.004
A8: MP503B | B8: He Tea tree BIO | C8: MELALEUCA ALTERNIFOLIA LEAF OIL | D8: TEA TREE HUILE ESSENTIELLE BIO | E8: Diffusions aromatiques | S8: 2 | AD8: 10 | AE8: 4 | AW8: 0.01 | BA8: 1 | BT8: 4 | EW8: 5 | FI8: 0.1 | FM8: 1
A9: MP504 | B9: He Shiu 98% | C9: CINNAMOMUM CAMPHORA LEAF OIL | D9: HO WOOD HE | E9: Diffusions aromatiques
A10: MP505B | B10: He Petit grain BIO | C10: CITRUS AURANTIUM LEAF OIL | D10: PETITGRAIN PARAGUAY HE BIO | E10: Diffusions aromatiques | I10: 0.7 | O10: 0.05 | S10: 3.5 | AD10: 0.1 | BA10: 1.5 | BB10: 0.01 | BM10: 0.01 | BT10: 7 | EW10: 2.3 | FF10: 0.1 | FI10: 4.5 | FL10: 0.01 | FM10: 30
A11: MP506B | B11: He Palmarosa BIO | C11: CYMBOPOGON MARTINI OIL | D11: PALMAROSA HE BIO Cymbopogon Martinii Bio | E11: Diffusions aromatiques
A12: MP507B | B12: He Orange sanguine | C12: CITRUS AURANTIUM DULCIS PEEL OIL | D12: ORANGE SANGUINE HUILE ESSENTIELLE | E12: Diffusions aromatiques | I12: 0.15 | S12: 96 | BT12: 0.05 | CS12: 100 | EW12: 0.75 | FM12: 0.2
A13: MP508B | B13: He Lavande fine BIO | C13: LAVANDULA ANGUSTIFOLIA OIL | D13: LAVANDE TRADITIONELLE FRANCE HE BIO | E13: Diffusions aromatiques | S13: 0.5 | AW13: 0.5 | BA13: 5.7 | BH13: 45 | BT13: 2 | DW13: 100 | EU13: 0.8 | EW13: 0.8 | FH13: 0.2 | FI13: 2 | FM13: 40
A14: MP510B | B14: He Géranium Rosat BIO | C14: PELARGONIUM GRAVEOLENS STEM LEAF OIL | D14: GERANIUM EGYPTE HE BIO | E14: Diffusions aromatiques | G14: 0.0075 | I14: 2 | O14: 39 | S14: 0.25 | AD14: 0.99 | EH14: 100 | FF14: 0.0065 | FI14: 20 | FM14: 8 | FN14: 0.0075
A15: MP511B | B15: He Citron incolore sans furocoumarine BIO | C15: Citrus Lemon Peel Oil | D15: CITRON RECTIFIE SANS FUROCOUMARINE WW / SB | E15: Diffusions aromatiques | S15: 70 | AD15: 0.2 | AE15: 0.3 | BA15: 0.3 | BT15: 0.2 | CY15: 100 | EU15: 0.2 | EW15: 16 | FI15: 0.04 | FM15: 0.2
A16: MP513B | B16: He Bergamotte incolore sans furocoumarine BIO | C16: CITRUS AURANTIUM BERGAMIA FRUIT OIL | D16: BERGAMOTE FCF HE ITALIE BIO | E16: Diffusions aromatiques | I16: 0.6 | S16: 45 | AD16: 0.2 | AE16: 0.35 | BA16: 0.3 | BT16: 0.2 | CT16: 100 | EU16: 0.35 | EW16: 11 | FI16: 0.04 | FM16: 15
A17: MP514 | B17: HE Baie Rose | C17: SCHINUS TEREBENTHIFOLIUS FRUIT OIL | D17: BAIES ROSES HE (schinus terebenthifolius) | E17: Diffusions aromatiques
A18: MP515B | B18: He Romarin Bio | C18: ROSMARINUS OFFICINALIS LEAF OIL | D18: ROMARIN CINEOL HUILE ESSENTIELLE BIO | E18: Diffusions aromatiques | S18: 5 | AD18: 0.4 | AW18: 10 | BA18: 3 | BT18: 2 | EW18: 24 | FM18: 0.75
A19: MP516B | B19: He Litsea Cubeba BIO | C19: LITSEA CUBEBA FRUIT OIL | D19: LITSEA CUBEBA HE BIO | E19: Diffusions aromatiques
A20: MP517 | B20: He Eucalyptus globulus | C20: EUCALYPTUS GLOBULUS LEAF OIL | D20: EUCALYPTUS GLOBULUS HE 80/85% | E20: Diffusions aromatiques
A21: MP519 | B21: He amande amère | C21: PRUNUS ARMENIACA KERNEL OIL | D21: AMANDE AMERE HE | E21: Diffusions aromatiques | G21: 1 | AV21: 99
A22: MP524 | B22: HE rose de Damas LM | C22: ROSA DAMASCENA FLOWER OIL | D22: ROSE HUILE ESSENTIELLE LOW METHYL EUGENOL | E22: Diffusions aromatiques | G22: 0.04 | I22: 2.5 | O22: 43 | S22: 0.1 | AD22: 0.05 | AG22: 0.1 | AV22: 0.12 | BA22: 0.5 | BM22: 0.05 | EU22: 3 | EW22: 5.5 | FB22: 0.3 | FF22: 0.01 | FI22: 25 | FL22: 2.4 | FM22: 2 | FN22: 0.15
A23: MP550 | B23: Fragrance Vanille TK 60669 | C23: Fragrance | D23: VANILLE TK 60669 | E23: Argeville
A24: MP551 | B24: Fruit de la passion NAT CO 60645 | C24: Fragrance | D24: FRUIT DE LA PASSION NAT CO 60645 | E24: Argeville | G24: 0.0039 | I24: 0.1326 | O24: 0.0072 | S24: 14.7328 | AD24: 0.0134 | AE24: 0.0199 | AV24: 0.5006 | BA24: 0.0122 | BB24: 0.0103 | BV24: 0.039 | CO24: 12.332 | CY24: 3.2 | EU24: 0.0241 | EW24: 0.8287 | FB24: 0.0015 | FG24: 0.5 | FI24: 0.0222 | FL24: 0.0013 | FM24: 0.0951
A25: MP552 | B25: Fragrance Code VAN Jasmin 3150/4 | C25: Fragrance | D25: C3150/4 | E25: VANESSENCE | G25: 0.0015 | I25: 0.016 | L25: 0.006 | S25: 1.239 | AD25: 0.0025 | AE25: 0.0109 | AU25: 0.0045 | AV25: 0.0015 | BA25: 0.2344 | BH25: 1.95 | BM25: 0.0045 | BU25: 0.187 | CC25: 0.0002 | CE25: 1.5 | CS25: 1 | CT25: 0.5 | EU25: 1.325 | EW25: 0.1037 | FA25: 0.0015 | FB25: 1.0315 | FF25: 0.06 | FG25: 0.0002 | FI25: 5.19 | FK25: 0.0002 | FL25: 0.042 | FM25: 18.76 | FN25: 0.15
A26: MP553 | B26: Fragrance fleur d'oranger | C26: Fragrance | D26: Composition Fleur oranger | E26: Laboratoire Rosier Davenne
A27: MP526 | B27: HE Néroli Tunisie | C27: Citrus Aurantium Flower Oil | D27: HE Néroli Tunisie | E27: Diffusions aromatiques
A28: MP202B | B28: =VLOOKUP(A28,Liste!A1:O1128,2,0) -> Hydrolat Menthe Poivrée BIO | C28: =VLOOKUP(A28,Liste!A1:O969,4,0) -> Mentha Piperita Leaf Water* | D28: =VLOOKUP(A28,Liste!A1:O955,2,0) -> Hydrolat Menthe Poivrée BIO | E28: =VLOOKUP(A28,Liste!A1:O953,3,0) -> Florihana | U28: 0.005 | BI28: 0.00281 | BU28: 0.001 | FM28: 0.005
A29: MP110B | B29: =VLOOKUP(A29,Liste!A2:O1129,2,0) -> Huile vierge de prune bio | C29: =VLOOKUP(A29,Liste!A2:O970,4,0) -> Prunus Domestica Seed Oil | D29: =VLOOKUP(A29,Liste!A2:O956,2,0) -> Huile vierge de prune bio | E29: =VLOOKUP(A29,Liste!A2:O953,3,0) -> Perle de Gascogne | G29: 0.015 | AV29: 0.25 | CC29: 0.003
A30: MP205B | B30: =VLOOKUP(A30,Liste!A3:O1130,2,0) -> Hydrolat de lavande fine sauvage BIO | C30: =VLOOKUP(A30,Liste!A3:O971,4,0) -> Lavandula Angustifolia Flower Water* | D30: =VLOOKUP(A30,Liste!A3:O957,2,0) -> Hydrolat de lavande fine sauvage BIO | E30: =VLOOKUP(A30,Liste!A3:O955,3,0) -> Florihana | U30: 0.001 | FH30: 0.001 | FI30: 0.001 | FM30: 0.025
A31: MP204B | B31: =VLOOKUP(A31,Liste!A4:O1131,2,0) -> Hydrolat de fleur d'oranger (Néroli) BIO non conservé | C31: =VLOOKUP(A31,Liste!A4:O972,4,0) -> Citrus Aurantium Amara Flower Water* | D31: =VLOOKUP(A31,Liste!A4:O958,2,0) -> Hydrolat de fleur d'oranger (Néroli) BIO non conservé | E31: =VLOOKUP(A31,Liste!A4:O956,3,0) -> Florihana | G31: 0.001 | I31: 0.001 | O31: 0.001 | U31: 0.001 | FB31: 0.001 | FI31: 0.005 | FL31: 0.002 | FM31: 0.02
A32: MP114B | B32: =VLOOKUP(A32,Liste!A5:O1132,2,0) -> Macérât de lavande bio | C32: =VLOOKUP(A32,Liste!A5:O973,4,0) -> Olea Europaea Fruit Oil* >99%, Lavandula Angustifolia Flower Extract*<1% | D32: =VLOOKUP(A32,Liste!A5:O959,2,0) -> Macérât de lavande bio | E32: =VLOOKUP(A32,Liste!A5:O957,3,0) -> La Canopée | AW32: 0.00175 | BA32: 0.00598 | BH32: 0.258 | FH32: 0.00141 | FM32: 0.0772
A33: MP200B | B33: =VLOOKUP(A33,Liste!A6:O1133,2,0) -> Hydrolat Rose damas Bio (conservé à 2% leucidal liquid) | C33: =VLOOKUP(A33,Liste!A6:O974,4,0) -> Rosa Damascena Flower Water* 98% 2% Leuconostoc/Radish Root Ferment Filtrate 50% (and) Aqua 50% | D33: =VLOOKUP(A33,Liste!A6:O960,2,0) -> Hydrolat Rose damas Bio (conservé à 2% leucidal liquid) | E33: =VLOOKUP(A33,Liste!A6:O958,3,0) -> Gazignaire | G33: 9e-05 | I33: 9e-05 | O33: 0.002 | BT33: 0.0001 | EK33: 0.012 | EU33: 9e-05 | FB33: 0.0004 | FI33: 0.004 | FM33: 0.0004
A34: ECH-ROS006 | B34: =VLOOKUP(A34,Liste!A7:O1134,2,0) -> Rose HE Bulgarie | C34: =VLOOKUP(A34,Liste!A7:O975,4,0) -> ROSA DAMASCENA FLOWER OIL | D34: =VLOOKUP(A34,Liste!A7:O961,2,0) -> Rose HE Bulgarie | E34: =VLOOKUP(A34,Liste!A7:O959,3,0) -> Atmosphaer | O34: 29.8 | EU34: 1.08 | FB34: 0.98 | FL34: 2 | FM34: 1.06
A35: MP523 | B35: =VLOOKUP(A35,Liste!A8:O1135,2,0) -> Vanilline | C35: =VLOOKUP(A35,Liste!A8:O976,4,0) -> Vanillin | D35: =VLOOKUP(A35,Liste!A8:O962,2,0) -> Vanilline | E35: =VLOOKUP(A35,Liste!A8:O960,3,0) -> Diffusions aromatiques
A36: MP201B | B36: =VLOOKUP(A36,Liste!A9:O1136,2,0) -> Hydrolat Fleur d'Oranger BIO (conservé) | C36: =VLOOKUP(A36,Liste!A9:O977,4,0) -> Citrus Aurantium Amara Flower water 98% Aqua 1% Leuconostoc/Radish Root Ferment Filtrate 1% | D36: =VLOOKUP(A36,Liste!A9:O963,2,0) -> Hydrolat Fleur d'Oranger BIO (conservé) | E36: =VLOOKUP(A36,Liste!A9:O961,3,0) -> Gazignaire | BT36: 0.015 | CL36: 0.03 | EU36: 0.0001 | FI36: 0.0003 | FM36: 0.025

Sheet IFRA
A2: IFRA CATÉGORIES | F2: Catégories | G2: 1 | H2: 2 | I2: 3 | J2: 4 | K2: 5A | L2: 5B | M2: 5D | N2: 6* | O2: 7A | P2: 7B | Q2: 8 | R2: 9 | S2: 10A | T2: 10B | U2: 11A | V2: 11B | W2: 12
F3: Description | G3: Produits appliqués sur les lèvres | H3: Produits appliqués sur les aisselles | I3: Produits appliqués sur le visage/corps du bout des doigts | J3: Produits liés à la Parfumerie fine | K3: Produits de lotion pour le corps appliqués sur le corps à l'aide des mains (paumes), principalement non rincés | L3: Produits hydratants pour le visage appliqués sur le visage à l'aide des mains (paumes). principalement non rincés | M3: Produits de crème pour les mains appliqués sur le mains en utilisant des mains (paumes), principalement non rincés | N3: Produits avec exposition orale et labiale | O3: Produits rincés appliqués sur les cheveux avec un certain contact avec les mains | P3: Produits non rincés appliqués sur les cheveux avec un certain contact avec les mains | Q3: Produits à exposition anogénitale importante | R3: Produits corps et mains, principalement rincés | S3: Produits d'entretien ménager avec contact principalement avec les mains à l'exclusion des produits aérosols et sprays | T3: Produits d'entretien ménager avec contact principalement avec les mains: produits aérosols et sprays | U3: Produits avec contact cutané prévu mais transfert minimal de parfum sur la peau sans exposition aux UV | V3: Produits avec contact cutané prévu mais transfert minimal de parfum sur la peau avec exposition aux UV | W3: Produits non destinés à un contact direct ave la peau
A4: MP501B | B4: He d'ylang ylang complète BIO | C4: CANANGA ODORATA FLOWER OIL | D4: YLANG COMPLETE HE BIO | E4: Diffusions aromatiques | G4: 100.0000% | H4: 55.0000% | I4: 100.0000% | J4: 100.0000% | K4: 60.0000% | L4: 100.0000% | M4: 100.0000% | N4: 100.0000% | O4: 90.0000% | P4: 100.0000% | Q4: 100.0000% | R4: 100.0000% | S4: 90.0000% | T4: 100.0000% | U4: 90.0000% | V4: 100.0000% | W4: 100.0000%
A5: MP502 | B5: He Vetiver Haïti BIO | C5: VETIVERIA ZIZANOIDES ROOT OIL | D5: VETYVER HAITI HUILE ESSENTIELLE | E5: Astier Demarest | M5: 0.06 | S5: 0.004
A6: MP503B | B6: He Tea tree BIO | C6: MELALEUCA ALTERNIFOLIA LEAF OIL | D6: TEA TREE HUILE ESSENTIELLE BIO | E6: Diffusions aromatiques | S6: 2
A7: MP504 | B7: He Shiu 98% | C7: CINNAMOMUM CAMPHORA LEAF OIL | D7: HO WOOD HE | E7: Diffusions aromatiques
A8: MP505B | B8: He Petit grain BIO | C8: CITRUS AURANTIUM LEAF OIL | D8: PETITGRAIN PARAGUAY HE BIO | E8: Diffusions aromatiques | I8: 0.7 | O8: 0.05 | S8: 3.5
A9: MP506B | B9: He Palmarosa BIO | C9: CYMBOPOGON MARTINI OIL | D9: PALMAROSA HE BIO Cymbopogon Martinii Bio | E9: Diffusions aromatiques
A10: MP507B | B10: He Orange sanguine | C10: CITRUS AURANTIUM DULCIS PEEL OIL | D10: ORANGE SANGUINE HUILE ESSENTIELLE | E10: Diffusions aromatiques | I10: 0.15 | S10: 96
A11: MP508B | B11: He Lavande fine BIO | C11: LAVANDULA ANGUSTIFOLIA OIL | D11: LAVANDE TRADITIONELLE FRANCE HE BIO | E11: Diffusions aromatiques | S11: 0.5
A12: MP510B | B12: He Géranium Rosat BIO | C12: PELARGONIUM GRAVEOLENS STEM LEAF OIL | D12: GERANIUM EGYPTE HE BIO | E12: Diffusions aromatiques | G12: 0.0075 | I12: 2 | O12: 39 | S12: 0.25
A13: MP511B | B13: He Citron incolore sans furocoumarine BIO | C13: Citrus Lemon Peel Oil | D13: CITRON RECTIFIE SANS FUROCOUMARINE WW / SB | E13: Diffusions aromatiques | S13: 70
A14: MP513B | B14: He Bergamotte incolore sans furocoumarine BIO | C14: CITRUS AURANTIUM BERGAMIA FRUIT OIL | D14: BERGAMOTE FCF HE ITALIE BIO | E14: Diffusions aromatiques | I14: 0.6 | S14: 45
A15: MP514 | B15: HE Baie Rose | C15: SCHINUS TEREBENTHIFOLIUS FRUIT OIL | D15: BAIES ROSES HE (schinus terebenthifolius) | E15: Diffusions aromatiques
A16: MP515B | B16: He Romarin Bio | C16: ROSMARINUS OFFICINALIS LEAF OIL | D16: ROMARIN CINEOL HUILE ESSENTIELLE BIO | E16: Diffusions aromatiques | S16: 5
A17: MP516B | B17: He Litsea Cubeba BIO | C17: LITSEA CUBEBA FRUIT OIL | D17: LITSEA CUBEBA HE BIO | E17: Diffusions aromatiques
A18: MP517 | B18: He Eucalyptus globulus | C18: EUCALYPTUS GLOBULUS LEAF OIL | D18: EUCALYPTUS GLOBULUS HE 80/85% | E18: Diffusions aromatiques
A19: MP519 | B19: He amande amère | C19: PRUNUS ARMENIACA KERNEL OIL | D19: AMANDE AMERE HE | E19: Diffusions aromatiques | G19: 1
A20: MP524 | B20: HE rose de Damas LM | C20: ROSA DAMASCENA FLOWER OIL | D20: ROSE HUILE ESSENTIELLE LOW METHYL EUGENOL | E20: Diffusions aromatiques | G20: 0.04 | I20: 2.5 | O20: 43 | S20: 0.1
A21: MP550 | B21: Fragrance Vanille TK 60669 | C21: Fragrance | D21: VANILLE TK 60669 | E21: Argeville
A22: MP551 | B22: Fruit de la passion NAT CO 60645 | C22: Fragrance | D22: FRUIT DE LA PASSION NAT CO 60645 | E22: Argeville | G22: 0.0039 | I22: 0.1326 | O22: 0.0072 | S22: 14.7328
A23: MP552 | B23: Fragrance Code VAN Jasmin 3150/4 | C23: Fragrance | D23: C3150/4 | E23: VANESSENCE | G23: 0.0015 | I23: 0.016 | L23: 0.006 | S23: 1.239
A24: MP553 | B24: Fragrance fleur d'oranger | C24: Fragrance | D24: Composition Fleur oranger | E24: Laboratoire Rosier Davenne
A25: MP526 | B25: HE Néroli Tunisie | C25: Citrus Aurantium Flower Oil | D25: HE Néroli Tunisie | E25: Diffusions aromatiques
A26: MP202B | B26: =VLOOKUP(A26,Liste!A1:O1128,2,0) -> Hydrolat Menthe Poivrée BIO | C26: =VLOOKUP(A26,Liste!A1:O969,4,0) -> Mentha Piperita Leaf Water* | D26: =VLOOKUP(A26,Liste!A1:O955,2,0) -> Hydrolat Menthe Poivrée BIO | E26: =VLOOKUP(A26,Liste!A1:O953,3,0) -> Florihana | U26: 0.005
A27: MP110B | B27: =VLOOKUP(A27,Liste!A2:O1129,2,0) -> Huile vierge de prune bio | C27: =VLOOKUP(A27,Liste!A2:O970,4,0) -> Prunus Domestica Seed Oil | D27: =VLOOKUP(A27,Liste!A2:O956,2,0) -> Huile vierge de prune bio | E27: =VLOOKUP(A27,Liste!A2:O953,3,0) -> Perle de Gascogne | G27: 0.015
A28: MP205B | B28: =VLOOKUP(A28,Liste!A3:O1130,2,0) -> Hydrolat de lavande fine sauvage BIO | C28: =VLOOKUP(A28,Liste!A3:O971,4,0) -> Lavandula Angustifolia Flower Water* | D28: =VLOOKUP(A28,Liste!A3:O957,2,0) -> Hydrolat de lavande fine sauvage BIO | E28: =VLOOKUP(A28,Liste!A3:O955,3,0) -> Florihana | U28: 0.001
A29: MP204B | B29: =VLOOKUP(A29,Liste!A4:O1131,2,0) -> Hydrolat de fleur d'oranger (Néroli) BIO non conservé | C29: =VLOOKUP(A29,Liste!A4:O972,4,0) -> Citrus Aurantium Amara Flower Water* | D29: =VLOOKUP(A29,Liste!A4:O958,2,0) -> Hydrolat de fleur d'oranger (Néroli) BIO non conservé | E29: =VLOOKUP(A29,Liste!A4:O956,3,0) -> Florihana | G29: 0.001 | I29: 0.001 | O29: 0.001 | U29: 0.001
A30: MP114B | B30: =VLOOKUP(A30,Liste!A5:O1132,2,0) -> Macérât de lavande bio | C30: =VLOOKUP(A30,Liste!A5:O973,4,0) -> Olea Europaea Fruit Oil* >99%, Lavandula Angustifolia Flower Extract*<1% | D30: =VLOOKUP(A30,Liste!A5:O959,2,0) -> Macérât de lavande bio | E30: =VLOOKUP(A30,Liste!A5:O957,3,0) -> La Canopée
A31: MP200B | B31: =VLOOKUP(A31,Liste!A6:O1133,2,0) -> Hydrolat Rose damas Bio (conservé à 2% leucidal liquid) | C31: =VLOOKUP(A31,Liste!A6:O974,4,0) -> Rosa Damascena Flower Water* 98% 2% Leuconostoc/Radish Root Ferment Filtrate 50% (and) Aqua 50% | D31: =VLOOKUP(A31,Liste!A6:O960,2,0) -> Hydrolat Rose damas Bio (conservé à 2% leucidal liquid) | E31: =VLOOKUP(A31,Liste!A6:O958,3,0) -> Gazignaire | G31: 9e-05 | I31: 9e-05 | O31: 0.002
A32: ECH-ROS006 | B32: =VLOOKUP(A32,Liste!A7:O1134,2,0) -> Rose HE Bulgarie | C32: =VLOOKUP(A32,Liste!A7:O975,4,0) -> ROSA DAMASCENA FLOWER OIL | D32: =VLOOKUP(A32,Liste!A7:O961,2,0) -> Rose HE Bulgarie | E32: =VLOOKUP(A32,Liste!A7:O959,3,0) -> Atmosphaer | O32: 29.8
A33: MP523 | B33: =VLOOKUP(A33,Liste!A8:O1135,2,0) -> Vanilline | C33: =VLOOKUP(A33,Liste!A8:O976,4,0) -> Vanillin | D33: =VLOOKUP(A33,Liste!A8:O962,2,0) -> Vanilline | E33: =VLOOKUP(A33,Liste!A8:O960,3,0) -> Diffusions aromatiques
A34: MP201B | B34: =VLOOKUP(A34,Liste!A9:O1136,2,0) -> Hydrolat Fleur d'Oranger BIO (conservé) | C34: =VLOOKUP(A34,Liste!A9:O977,4,0) -> Citrus Aurantium Amara Flower water 98% Aqua 1% Leuconostoc/Radish Root Ferment Filtrate 1% | D34: =VLOOKUP(A34,Liste!A9:O963,2,0) -> Hydrolat Fleur d'Oranger BIO (conservé) | E34: =VLOOKUP(A34,Liste!A9:O961,3,0) -> Gazignaire

Sheet Test allergènes
D2: Test pour allergènes à déclarer
C4: % de la substance allergène dans la matière première / % of the allergenic substance in the raw material
C5: % de la substance allergène dans le produit fini / % of the allergenic substance in the finished product
F6: Allergènes | G6: Benzyl alcohol | I6: 6-Methylcoumarin | K6: Citral | M6: Geranial | O6: Neral | Q6: Isoeugenol | S6: Isoeugenol | U6: Isoeugenol | W6: Citronellol | Y6: Citronellol | AA6: Citronellol | AC6: Citronellol | AE6: Limonene | AG6: Limonene | AI6: Limonene | AK6: Limonene | AM6: Pinus Mugo Leaf Oil Pinus Mugo Twig Leaf Extract Pinus Mugo Twig Oil | AO6: Pinus Pumila needle extract Pinus Pumila Twig Leaf Extract Pinus Pumila Twig Leaf Oil | AQ6: Cedrus Atlantica Bark Extract Cedrus Atlantica Bark Oil Cedrus Atlantica Bark Water Cedrus Atlantica Leaf Extract Cedrus Atlantica Wood Extract Cedrus Atlantica Wood Oil | AS6: Cedrus Atlantica Bark Extract Cedrus Atlantica Bark Oil Cedrus Atlantica Bark Water Cedrus Atlantica Leaf Extract Cedrus Atlantica Wood Extract Cedrus Atlantica Wood Oil | AU6: Turpentine | AW6: Turpentine | AY6: Turpentine | BA6: Alpha-terpinene | BC6: Terpinolene | BE6: Myroxylon Balsamum Pereirae Balsam Extract; Myroxylon Balsamum Pereirae Balsam Oil; Myroxylon Pereirae Oil; Myroxylon Pereirae Resin Extract; Myroxylon Pereirae Resin | BG6: Aalpha-Damascone; cis-Rose ketone 1 cis Rose ketone 2 (cis-beta-Damascone); trans-Rose ketone 2 (trans-beta-Damascone) | BI6: Aalpha-Damascone; cis-Rose ketone 1 | BK6: trans-Rose ketone 1 | BM6: Rose ketone 4 (Damascenone) | BO6: Rose ketone 3 (delta-Damascone) | BQ6: trans-Rose ketone 3 | BS6: cis Rose ketone 2 (cis-beta-Damascone) | BU6: trans-Rose ketone 2 (trans-beta-Damascone) | BW6: 3-Propylidenephthalide | BY6: Lippia citriodora absolute | CA6: Lippia citriodora absolute | CC6: Acetyl Cedrene | CE6: Amyl Salicylate | CG6: Anethole | CI6: Anethole | CK6: Benzaldehyde | CM6: Camphor | CO6: Camphor | CQ6: Camphor | CS6: Camphor | CU6: Beta-Caryophyllene | CW6: Carvone | CY6: Carvone | DA6: Carvone | DC6: Dimethyl phenethyl Acetate | DE6: Hexadecanolactone | DG6: Hexamethylindanopyran | DI6: Linalyl Acetate | DK6: Menthol | DM6: Menthol | DO6: Menthol | DQ6: Menthol | DS6: Methyl Salicylate | DU6: Ebanol | DW6: Salicylaldehyde | DY6: Santalol | EA6: Santalol | EC6: Santalol | EE6: Sclareol | EG6: Terpineol | EI6: Alpha Terpineol | EK6: Terpineol | EM6: Terpineol | EO6: Tetramethyl acetyloctahydronaphthalenes | EQ6: Tetramethyl acetyloctahydronaphthalenes | ES6: Tetramethyl acetyloctahydronaphthalenes | EU6: Tetramethyl acetyloctahydronaphthalenes | EW6: Trimethylbenzenepropanol | EY6: Vanillin | FA6: Cananga Odorata Flower Extract | FC6: Cananga Odorata Flower Extract | FE6: Cananga Odorata Flower Oil | FG6: Cananga Odorata Flower Oil | FI6: Cinnamomum Cassia Leaf Oil | FK6: Cinnamomum Cassia Leaf Oil | FM6: Cinnamomum Zeylanicum Bark Oil | FO6: Cinnamomum Zeylanicum Bark Oil | FQ6: Citrus Aurantium Amara Flower Oil | FS6: Citrus Aurantium Dulcis Flower Oil | FU6: Citrus Aurantium Dulcis Flower Oil | FW6: Citrus Aurantium Amara Peel Oil Citrus Sinensis Peel Oil | FY6: Citrus Aurantium Amara Peel Oil | GA6: Citrus Sinensis Peel Oil | GC6: Citrus Aurantium Dulcis Peel Oil; Citrus Sinensis Peel Oil | GE6: Citrus Aurantium Dulcis Peel Oil; Citrus Sinensis Peel Oil | GG6: Citrus Aurantium Bergamia Peel Oil | GI6: Citrus Aurantium Bergamia Peel Oil | GK6: Citrus Aurantium Bergamia Peel Oil | GM6: Citrus Aurantium Bergamia Peel Oil | GO6: Citrus Aurantium Bergamia Peel Oil | GQ6: Citrus Limon Peel Oil | GS6: Citrus Limon Peel Oil | GU6: Cymbopogon Schoenantus Oil | GW6: Cymbopogon Schoenantus Oil | GY6: Cymbopogon Citratus Leaf Oil Cymbopogon Flexuosus Oil | HA6: Eucalyptus Globulus Leaf Oil Eucalyptus Globulus Leaf/Twig Oil | HC6: Eucalyptus Globulus Leaf Oil Eucalyptus Globulus Leaf/Twig Oil | HE6: Eugenia Caryophyllus Leaf Oil Eugenia Caryophyllus Flower Oil Eugenia Caryophyllus Stem Oil Eugenia Caryophyllus Bud Oil | HG6: Eugenia Caryophyllus Leaf Oil Eugenia Caryophyllus Flower Oil Eugenia Caryophyllus Stem Oil Eugenia Caryophyllus Bud Oil | HI6: Eugenia Caryophyllus Leaf Oil Eugenia Caryophyllus Flower Oil Eugenia Caryophyllus Stem Oil Eugenia Caryophyllus Bud Oil | HK6: Jasminum Grandiflorum Flower Extract; Jasminum Officinale Oil Jasminum Officinale Flower Extract; | HM6: Jasminum Grandiflorum Flower Extract; Jasminum Officinale Oil Jasminum Officinale Flower Extract; | HO6: Jasminum Grandiflorum Flower Extract; Jasminum Officinale Oil Jasminum Officinale Flower Extract; | HQ6: Jasminum Grandiflorum Flower Extract; Jasminum Officinale Oil Jasminum Officinale Flower Extract; | HS6: Jasminum Grandiflorum Flower Extract; Jasminum Officinale Oil Jasminum Officinale Flower Extract; | HU6: Juniperus Virginiana Oil; Juniperus Virginiana Wood Oil | HW6: Laurus Nobilis Leaf Oil | HY6: Laurus Nobilis Leaf Oil | IA6: Laurus Nobilis Leaf Oil | IC6: Lavandula Hybrida Oil; Lavandula Hybrida Extract; Lavandula Hybrida Flower Extract; | IE6: Lavandula Hybrida Oil; Lavandula Hybrida Extract; Lavandula Hybrida Flower Extract; | IG6: Lavandula Hybrida Oil; Lavandula Hybrida Extract; Lavandula Hybrida Flower Extract; | II6: Lavandula Hybrida Oil; Lavandula Hybrida Extract; Lavandula Hybrida Flower Extract; | IK6: Lavandula Hybrida Oil; Lavandula Hybrida Extract; Lavandula Hybrida Flower Extract; | IM6: Lavandula Intermedia Flower/Leaf/Stem Extract; Lavandula Intermedia Flower/Leaf/Stem Oil; Lavandula intermedia Oil Lavendula Angustifolia Oil; Lavendula Angustifolia Flower/Leaf/Stem Extract | IO6: Lavandula Intermedia Flower/Leaf/Stem Extract; Lavandula Intermedia Flower/Leaf/Stem Oil; Lavandula intermedia Oil Lavendula Angustifolia Oil; Lavendula Angustifolia Flower/Leaf/Stem Extract | IQ6: Mentha Piperita Oil | IS6: Mentha Piperita Oil | IU6: Mentha Viridis Leaf Oil | IW6: Mentha Viridis Leaf Oil | IY6: Narcissus Poeticus Extract Narcissus Pseudonarcissus Flower Extract Narcissus Jonquilla Extract Narcissus Tazetta Extract | JA6: Narcissus Poeticus Extract Narcissus Pseudonarcissus Flower Extract Narcissus Jonquilla Extract Narcissus Tazetta Extract | JC6: Narcissus Poeticus Extract Narcissus Pseudonarcissus Flower Extract Narcissus Jonquilla Extract Narcissus Tazetta Extract | JE6: Narcissus Poeticus Extract Narcissus Pseudonarcissus Flower Extract Narcissus Jonquilla Extract Narcissus Tazetta Extract | JG6: Pelargonium Graveolens Flower Oil | JI6: Pelargonium Graveolens Flower Oil | JK6: Pogostemon Cablin Oil | JM6: Pogostemon Cablin Oil | JO6: Rosa Damascena Flower Oil; Rosa Damascena Flower Extract Rosa Alba Flower Oil; Rosa Alba Flower Extract Rosa Canina Fruit Oil Rosa Centifolia Flower Oil; Rosa Centifolia Flower Extract Rosa Gallica Flower Oil Rosa Moschata Flower Oil Rosa Rugosa Flower Oil | JQ6: Rosa Damascena Flower Oil; Rosa Damascena Flower Extract Rosa Alba Flower Oil; Rosa Alba Flower Extract Rosa Canina Fruit Oil Rosa Centifolia Flower Oil; Rosa Centifolia Flower Extract Rosa Gallica Flower Oil Rosa Moschata Flower Oil Rosa Rugosa Flower Oil | JS6: Rosa Damascena Flower Oil; Rosa Damascena Flower Extract Rosa Alba Flower Oil; Rosa Alba Flower Extract Rosa Canina Fruit Oil Rosa Centifolia Flower Oil; Rosa Centifolia Flower Extract Rosa Gallica Flower Oil Rosa Moschata Flower Oil Rosa Rugosa Flower Oil | JU6: Rosa Damascena Flower Oil; Rosa Damascena Flower Extract Rosa Alba Flower Oil; Rosa Alba Flower Extract Rosa Canina Fruit Oil Rosa Centifolia Flower Oil; Rosa Centifolia Flower Extract Rosa Gallica Flower Oil Rosa Moschata Flower Oil Rosa Rugosa Flower Oil | JW6: Rosa Damascena Flower Oil; Rosa Damascena Flower Extract Rosa Alba Flower Oil; Rosa Alba Flower Extract Rosa Canina Fruit Oil Rosa Centifolia Flower Oil; Rosa Centifolia Flower Extract Rosa Gallica Flower Oil Rosa Moschata Flower Oil Rosa Rugosa Flower Oil | JY6: Rosa Damascena Flower Oil; Rosa Damascena Flower Extract Rosa Alba Flower Oil; Rosa Alba Flower Extract Rosa Canina Fruit Oil Rosa Centifolia Flower Oil; Rosa Centifolia Flower Extract Rosa Gallica Flower Oil Rosa Moschata Flower Oil Rosa Rugosa Flower Oil | KA6: Rosa Damascena Flower Oil; Rosa Damascena Flower Extract Rosa Alba Flower Oil; Rosa Alba Flower Extract Rosa Canina Fruit Oil Rosa Centifolia Flower Oil; Rosa Centifolia Flower Extract Rosa Gallica Flower Oil Rosa Moschata Flower Oil Rosa Rugosa Flower Oil | KC6: Santalum Album Oil | KE6: Santalum Album Oil | KG6: Eugenyl Acetate | KI6: Geranyl Acetate | KK6: Isoeugenyl Acetate | KM6: Pinene | KO6: Pinene | KQ6: Pinene | KS6: Pinene | KU6: Cinnamyl alcohol | KW6: Eugenol | KY6: Hydroxycitronellal | LA6: Amyl cinnamal | LC6: Amylcinnamyl alcohol | LE6: Benzyl salicylate | LG6: Cinnamal | LI6: Coumarin | LK6: Geraniol | LM6: Anise alcohol | LO6: Benzyl cinnamate | LQ6: Farnesol | LS6: Linalool | LU6: Benzyl benzoate | LW6: Hexyl cinnamal | LY6: Methyl 2-octynoate | MA6: Alpha isomethyl ionone | MC6: butylphenyl methylpropional | ME6: evernia furfuracea (treemoss) extract | MG6: evernia prunastri (oak moss) extract | MI6: hydroxyisohexyl 3-cyclohexene carboxaldehyde
A7: Référence MP interne RM internal reference | B7: Description | C7: INCI | D7: Dénomination commerciale MP Commercial RM name | E7: % (m / m) MP dans la formule % (w / w) RM in the formula | F7: N°CAS | G7: 100-51-6 | I7: 92-48-8 | K7: 5392-40-5 | M7: 141-27-5 | O7: 106-26-3 | Q7: 97-54-1 | S7: 5932-68-3 | U7: 5912-86-7 | W7: 106-22-9 | Y7: 26489-01-0 | AA7: 1117-61-9 | AC7: 7540-51-4 | AE7: 138-86-3 | AG7: 7705-14-8 | AI7: 5989-27-5 | AK7: 5989-54-8 | AM7: 90082-72-7 | AO7: 97676-05-6 | AQ7: 92201-55-3 | AS7: 8023-85-6 | AU7: 9005-90-7 | AW7: 8006-64-2 | AY7: 8052-14-0 | BA7: 99-86-5 | BC7: 586-62-9 | BE7: 8007-00-9 | BG7: 43052-87-5 | BI7: 23726-94-5 | BK7: 24720-09-0 | BM7: 23696-85-7 | BO7: 57378-68-4 | BQ7: 71048-82-3 | BS7: 23726-92-3 | BU7: 23726-91-2 | BW7: 17369-59-4 | BY7: 8024-12-2 | CA7: 85116-63-8 | CC7: 32388-55-9 | CE7: 2050-08-0 | CG7: 104-46-1 | CI7: 4180-23-8 | CK7: 100-52-7 | CM7: 76-22-2 | CO7: 21368-68-3 | CQ7: 464-49-3 | CS7: 464-48-2 | CU7: 87-44-5 | CW7: 99-49-0 | CY7: 6485-40-1 | DA7: 2244-16-8 | DC7: 151-05-3 | DE7: 109-29-5 | DG7: 1222-05-5 | DI7: 115-95-7 | DK7: 89-78-1 | DM7: 1490-04-6 | DO7: 2216-51-5 | DQ7: 15356-60-2 | DS7: 119-36-8 | DU7: 67801-20-1 | DW7: 90-02-8 | DY7: 11031-45-1 | EA7: 115-71-9 | EC7: 77-42-9 | EE7: 515-03-7 | EG7: 8000-41-7 | EI7: 98-55-5 | EK7: 138-87-4 | EM7: 586-81-2 | EO7: 54464-57-2 | EQ7: 54464-59-4 | ES7: 68155-66-8 | EU7: 68155-67-9 | EW7: 103694-68-4 | EY7: 121-33-5 | FA7: 83863-30-3 | FC7: 8006-81-3 | FE7: 68606-83-7 | FG7: 93686-30-7 | FI7: 8007-80-5 | FK7: 84961-46-6 | FM7: 8015-91-6 | FO7: 84649-98-9 | FQ7: 72968-50-4 | FS7: 8028-48-6 | FU7: 8016-38-4 | FW7: 68916-04-1 | FY7: 72968-50-4 | GA7: 97766-30-8 | GC7: 8028-48-6 | GE7: 8008-57-9 | GG7: 8007-75-8 | GI7: 89957-91-5 | GK7: 68648-33-9 | GM7: 8007-75-8 | GO7: 85049-52-1 | GQ7: 84929-31-7 | GS7: 8008-56-8 | GU7: 8007-02-1 | GW7: 89998-16-3 | GY7: 91844-92-7 | HA7: 97926-40-4 | HC7: 8000-48-4 | HE7: 8000-34-8 | HG7: 84961-50-2 | HI7: 8015-97-2 | HK7: 84776-64-7 | HM7: 90045-94-6 | HO7: 8022-96-6 | HQ7: 8024-43-9 | HS7: 90045-94-6 | HU7: 8000-27-9/ 85085-41-2 | HW7: 8002-41-3 | HY7: 8007-48-5 | IA7: 84603-73-6 | IC7: 91722-69-9 | IE7: 8022-15-9 | IG7: 93455-96-0 | II7: 93455-97-1 | IK7: 92623-76-2 | IM7: 8000-28-0 | IO7: 90063-37-9 | IQ7: 8006-90-4 | IS7: 84082-70-2 | IU7: 8008-79-5 | IW7: 84696-51-5 | IY7: 90064-26-9 | JA7: 68917-12-4 | JC7: 90064-27-0 | JE7: 90064-25-8 | JG7: 90082-51-2 | JI7: 8000-46-2 | JK7: 8014-09-3 | JM7: 84238-39-1 | JO7: 8007-01-0 | JQ7: 90106-38-0 | JS7: 93334-48-6 | JU7: 84696-47-9 | JW7: 84604-12-6 | JY7: 84604-13-7 | KA7: 92347-25-6 | KC7: 8006-87-9 | KE7: 84787-70-2 | KG7: 93-28-7 | KI7: 105-87-3 | KK7: 93-29-8 | KM7: 80-56-8 | KO7: 7785-70-8 | KQ7: 127-91-3 | KS7: 18172-67-3 | KU7: 104-54-1 | KW7: 97-53-0 | KY7: 107-75-5 | LA7: 122-40-7 | LC7: 101-85-9 | LE7: 118-58-1 | LG7: 104-55-2 | LI7: 91-64-5 | LK7: 106-24-1 | LM7: 105-13-5 | LO7: 103-41-3 | LQ7: 4602-84-0 | LS7: 78-70-6 | LU7: 120-51-4 | LW7: 101-86-0 | LY7: 111-12-6 | MA7: 127-51-5 | MC7: 80-54-6 | ME7: 90028-67-4 | MG7: 90028-68-5 | MI7: 31906-04-4
F8: Groupements | K8: Citral | M8: Citral | O8: Citral | AM8: Pinus Mugo | AO8: Pinus Pumila | AQ8: Cedrus Atlantica | AS8: Cedrus Atlantica | BE8: Myroxylon Pereirae Oil/Extract | BG8: Rose Ketones | BI8: Rose Ketones | BK8: Rose Ketones | BM8: Rose Ketones | BO8: Rose Ketones | BQ8: Rose Ketones | BS8: Rose Ketones | BU8: Rose Ketones | FA8: Cananga Odorata Oil/Extract | FC8: Cananga Odorata Oil/Extract | FE8: Cananga Odorata Oil/Extract | FG8: Cananga Odorata Oil/Extract | FQ8: Citrus Aurantium Flower Oil | FS8: Citrus Aurantium Flower Oil | FU8: Citrus Aurantium Flower Oil | FW8: Citrus Aurantium Peel oil | FY8: Citrus Aurantium Peel oil | GA8: Citrus Aurantium Peel oil | GC8: Citrus Aurantium Peel oil | GE8: Citrus Aurantium Peel oil | GU8: Lemongrass Oil | GW8: Lemongrass Oil | GY8: Lemongrass Oil | HA8: Eucalyptus Globulus Oil | HC8: Eucalyptus Globulus Oil | HE8: Eugenia Caryophyllus Oil | HG8: Eugenia Caryophyllus Oil | HI8: Eugenia Caryophyllus Oil | HK8: Jasmine Oil/Extract | HM8: Jasmine Oil/Extract | HO8: Jasmine Oil/Extract | HQ8: Jasmine Oil/Extract | HS8: Jasmine Oil/Extract | HU8: Juniperus Virginiana Oil | IC8: Lavandula Oil/Extract | IE8: Lavandula Oil/Extract | IG8: Lavandula Oil/Extract | II8: Lavandula Oil/Extract | IK8: Lavandula Oil/Extract | IM8: Lavandula Oil/Extract | IO8: Lavandula Oil/Extract | IY8: Narcissus Extract | JA8: Narcissus Extract | JC8: Narcissus Extract | JE8: Narcissus Extract | JO8: Rose Flower Oil/Extract | JQ8: Rose Flower Oil/Extract | JS8: Rose Flower Oil/Extract | JU8: Rose Flower Oil/Extract | JW8: Rose Flower Oil/Extract | JY8: Rose Flower Oil/Extract | KA8: Rose Flower Oil/Extract
